<?xml version="1.0" ?>
<!-- Generated using onshape-to-robot -->
<!-- Onshape https://cad.onshape.com/documents/3ebbb10823be46a55188b1ff/w/2488f47398571f659f3fde55/e/50a5d975662b86366b46b910 -->
<robot name="doublePendulem">
  <!-- Link base -->

  <!-- Connection to world frame -->
  <link name="world"/>
  <joint name="world_to_base" type="fixed">
      <parent link="world"/>
      <child link="base"/>
      <origin xyz="0 0 0" rpy="0 0 0"/>
  </joint>

  <link name="base">
    <inertial>
      <origin xyz="0 0 0" rpy="0 0 0"/>
      <mass value="0"/>
      <inertia ixx="0" ixy="0" ixz="0" iyy="0" iyz="0" izz="0"/>
    </inertial>
    <!-- Part base -->
    <visual>
      <origin xyz="0 0 0" rpy="0 -0 0"/>
      <geometry>
        <mesh filename="../meshes/base.obj"/>
      </geometry>
      <material name="base_material">
        <color rgba="0.615686 0.811765 0.929412 1.0"/>
      </material>
    </visual>
    <collision>
      <origin xyz="0 0 0" rpy="0 -0 0"/>
      <geometry>
        <mesh filename="../meshes/base.obj"/>
      </geometry>
    </collision>
  </link>
  <!-- Link link1 -->
  <link name="link1">
    <inertial>
      <origin xyz="-2.29364e-17 -0.788918 -0.0234433" rpy="0 0 0"/>
      <mass value="131.03"/>
      <inertia ixx="30.0942" ixy="5.11625e-16" ixz="0" iyy="0.463331" iyz="0.145044" izz="30.4804"/>
    </inertial>
    <!-- Part link1 -->
    <visual>
      <origin xyz="0 -3.06162e-18 -0.11" rpy="-1.5708 -0 0"/>
      <geometry>
        <mesh filename="../meshes/link1.obj"/>
      </geometry>
      <material name="link1_material">
        <color rgba="0.647059 0.647059 0.647059 1.0"/>
      </material>
    </visual>
    <collision>
      <origin xyz="0 -3.06162e-18 -0.11" rpy="-1.5708 -0 0"/>
      <geometry>
        <mesh filename="../meshes/link1.obj"/>
      </geometry>
    </collision>
  </link>
  <!-- Link link2 -->
  <link name="link2">
    <inertial>
      <origin xyz="-1.64499e-16 -0.768205 -0.025" rpy="0 0 0"/>
      <mass value="127.322"/>
      <inertia ixx="28.15" ixy="2.1371e-16" ixz="0" iyy="0.448999" iyz="0" izz="28.5459"/>
    </inertial>
    <!-- Part link2 -->
    <visual>
      <origin xyz="0 1.5 -0.17" rpy="-1.5708 -0 0"/>
      <geometry>
        <mesh filename="../meshes/link2.obj"/>
      </geometry>
      <material name="link2_material">
        <color rgba="0.231373 0.380392 0.705882 1.0"/>
      </material>
    </visual>
    <collision>
      <origin xyz="0 1.5 -0.17" rpy="-1.5708 -0 0"/>
      <geometry>
        <mesh filename="../meshes/link2.obj"/>
      </geometry>
    </collision>
  </link>
  <!-- Joint from link1 to link2 -->
  <joint name="joint2" type="continuous">
    <origin xyz="0 -1.5 0.06" rpy="0 -0 0"/>
    <parent link="link1"/>
    <child link="link2"/>
    <axis xyz="0 0 1"/>
    <limit effort="1000" velocity="600"/>
    <joint_properties friction="0.5"/>
    <dynamics damping="15" friction="100"/>
  </joint>
  <!-- Joint from base to link1 -->
  <joint name="joint1" type="continuous">
    <origin xyz="0 -0.11 3.06162e-18" rpy="1.5708 -0 0"/>
    <parent link="base"/>
    <child link="link1"/>
    <axis xyz="0 0 1"/>
    <limit effort="1000" velocity="600"/>
    <joint_properties friction="0.5"/>
    <dynamics damping="15" friction="100"/>
  </joint>
</robot>
