<?xml version="1.0"?>
<!-- Generated using onshape-to-robot -->
<!-- Onshape
https://cad.onshape.com/documents/15c938082851fbd4bacdce98/w/82abc59e7a8e49fa89bdf240/e/6eccd0fe0e79791f0e511e8b -->
<robot name="leg_visual">
    <!-- Connection to world frame -->
    <link name="world" />
    <joint name="world_to_bodysection" type="fixed">
        <parent link="world" />
        <child link="bodysectiona" />
        <origin xyz="0 0 1.0" rpy="0 0 0" />
    </joint>
    <!-- Link bodysectiona -->
    <link name="bodysectiona">
        <inertial>
            <origin xyz="0.0541647 -0.0878839 0.000234002" rpy="0 0 0" />
            <mass value="2.333" />
            <inertia ixx="0.00425967" ixy="-0.00247989" ixz="4.14274e-05" iyy="0.011561"
                iyz="1.17403e-05" izz="0.014638" />
        </inertial>
        <!-- Part bodysectiona -->
        <visual>
            <origin xyz="0 0 0" rpy="0 -0 0" />
            <geometry>
                <mesh filename="../meshes/bodysectiona.obj" />
            </geometry>
            <material name="bodysectiona_material">
                <color rgba="0.972549 0.529412 0.00392157 1.0" />
            </material>
        </visual>
        <collision>
            <origin xyz="0 0 0" rpy="0 -0 0" />
            <geometry>
                <mesh filename="../meshes/bodysectioncola.obj" />
            </geometry>
        </collision>
        <collision>
            <origin xyz="0 0 0" rpy="0 -0 0" />
            <geometry>
                <box size="0.27160362 0.14680000 0.082"/>
            </geometry>
        </collision>
    </link>
    <!-- Link coxamerger -->
    <link name="coxamerger">
        <inertial>
            <origin xyz="-0.0100851 0.000391481 -0.0598052" rpy="0 0 0" />
            <mass value="1.5" />
            <inertia ixx="0.00120555" ixy="1.25099e-05" ixz="-5.55819e-05" iyy="0.00233404"
                iyz="2.28685e-06" izz="0.00180944" />
        </inertial>
        <!-- Part coxamerger -->
        <visual>
            <origin xyz="0 0 -0.0635" rpy="3.14159 0 0" />
            <geometry>
                <mesh filename="../meshes/coxamerger.obj" />
            </geometry>
            <material name="coxamerger_material">
                <color rgba="0.768627 0.886275 0.952941 1.0" />
            </material>
        </visual>
        <!-- <collision>
            <origin xyz="0 0 -0.0635" rpy="3.14159 0 0" />
            <geometry>
                <mesh filename="../meshes/coxamergecolr.obj" />
            </geometry>
        </collision> -->
        <collision>
            <origin xyz="-0.005 0.0 -0.064" rpy="1.5708 0.0 1.5708" />
            <geometry>
                <cylinder radius="0.0385" length="0.163" />
            </geometry>
        </collision>
    </link>
    <!-- Link femurmerger -->
    <link name="femurmerger">
        <inertial>
            <origin xyz="0.0750029 -0.00474222 0.0593829" rpy="0 0 0" />
            <mass value="1.952" />
            <inertia ixx="0.00147688" ixy="0.0015025" ixz="-0.000685788" iyy="0.0275279"
                iyz="4.34335e-05" izz="0.0271576" />
        </inertial>
        <!-- Part femurmerger -->
        <visual>
            <origin xyz="0 0 0.064" rpy="0 0 0" />
            <geometry>
                <mesh filename="../meshes/femurmerger.obj" />
            </geometry>
            <material name="femurmerger_material">
                <color rgba="0.917647 0.917647 0.917647 1.0" />
            </material>
        </visual>
        <!-- <collision>
            <origin xyz="0 0 0.064" rpy="0 0 0" />
            <geometry>
                <mesh filename="../meshes/femurmergecolr.obj" />
            </geometry>
        </collision> -->
        <collision>
            <origin xyz="0.14 -0.01 0.064" rpy="1.5708 0.0 1.50328582545" />
            <geometry>
                <cylinder radius="0.0355" length="0.47" />
            </geometry>
        </collision>
    </link>
    <!-- Link tibiamerger -->
    <link name="tibiamerger">
        <inertial>
            <origin xyz="0.201087 0.0069932 -4.84705e-05" rpy="0 0 0" />
            <mass value="0.219992" />
            <inertia ixx="5.27818e-05" ixy="-0.00010343" ixz="-1.28273e-08" iyy="0.0053374"
                iyz="2.83936e-08" izz="0.00534035" />
        </inertial>
        <!-- Part tibiamerger -->
        <visual>
            <origin xyz="0 0 0" rpy="0 -0 0" />
            <geometry>
                <mesh filename="../meshes/tibiamerger.obj" />
            </geometry>
            <material name="tibiamerger_material">
                <color rgba="0.231373 0.380392 0.705882 1.0" />
            </material>
        </visual>
        <!-- <collision>
            <origin xyz="0 0 0" rpy="0 0 0" />
            <geometry>
                <mesh filename="../meshes/tibiamergecolr.obj" />
            </geometry>
        </collision> -->
        <collision>
            <origin xyz="0.36328592 0.0 0.0 " rpy="0.0 0.0 0.0" />
            <geometry>
                <sphere radius="0.025" />
            </geometry>
        </collision>
        <collision>
            <origin xyz="0.14 0.007 0.0" rpy="1.5708 0.0 1.6191272514" />
            <geometry>
                <cylinder radius="0.02" length="0.41" />
            </geometry>
        </collision>
    </link>
    <!-- Joint from femurmerger to tibiamerger -->
    <joint name="j2" type="revolute">
        <origin xyz="0.370594 0 0.064" rpy="0 0 -1.5708" />
        <parent link="femurmerger" />
        <child link="tibiamerger" />
        <axis xyz="0 0 1" />
        <limit effort="30" velocity="300" lower="-31.41592653589793" upper="31.41592653589793" />
        <dynamics damping="3.0" friction="50" />
    </joint>
    <!-- Joint from coxamerger to femurmerger -->
    <joint name="j1" type="revolute">
        <origin xyz="0.055 0 -0.0635" rpy="0 1.5708 0" />
        <parent link="coxamerger" />
        <child link="femurmerger" />
        <axis xyz="0 0 1" />
        <limit effort="30" velocity="300" lower="-31.41592653589793" upper="31.41592653589793" />
        <dynamics damping="3.0" friction="50" />
    </joint>
    <!-- Joint from bodysectiona to coxamerger -->
    <joint name="j0" type="revolute">
        <origin xyz="0.0996 -0.106 0" rpy="1.5708 0 -1.5708" />
        <parent link="bodysectiona" />
        <child link="coxamerger" />
        <axis xyz="0 0 1" />
        <limit effort="30" velocity="300" lower="-31.41592653589793" upper="31.41592653589793" />
        <dynamics damping="3.0" friction="50" />
    </joint>
</robot>