<?xml version="1.0" ?>
<!-- Generated using onshape-to-robot -->
<!-- Onshape https://cad.onshape.com/documents/3ebbb10823be46a55188b1ff/w/2488f47398571f659f3fde55/e/50a5d975662b86366b46b910 -->
<robot name="doublePendulem">
  <!-- Link base -->
  <link name="base">
    <inertial>
      <origin xyz="-1.15939e-17 -0.0302136 1.87906e-17" rpy="0 0 0"/>
      <mass value="13.5218"/>
      <inertia ixx="0.0990454" ixy="0" ixz="0" iyy="0.185202" iyz="0" izz="0.0990454"/>
    </inertial>
    <!-- Part base -->
    <visual>
      <origin xyz="0 0 0" rpy="0 -0 0"/>
      <geometry>
        <mesh filename="package://assets/base.stl"/>
      </geometry>
      <material name="base_material">
        <color rgba="0.615686 0.811765 0.929412 1.0"/>
      </material>
    </visual>
    <collision>
      <origin xyz="0 0 0" rpy="0 -0 0"/>
      <geometry>
        <mesh filename="package://assets/base.stl"/>
      </geometry>
    </collision>
  </link>
  <!-- Link link1 -->
  <link name="link1">
    <inertial>
      <origin xyz="-1.32046e-17 -0.637977 -0.0231011" rpy="0 0 0"/>
      <mass value="37.1262"/>
      <inertia ixx="5.71829" ixy="1.47509e-16" ixz="1.07742e-60" iyy="0.131211" iyz="0.0396211" izz="5.82631"/>
    </inertial>
    <!-- Part link1 -->
    <visual>
      <origin xyz="4.49945e-74 -3.06162e-18 -0.11" rpy="-1.5708 3.19605e-84 -7.81881e-72"/>
      <geometry>
        <mesh filename="package://assets/link1.stl"/>
      </geometry>
      <material name="link1_material">
        <color rgba="0.647059 0.647059 0.647059 1.0"/>
      </material>
    </visual>
    <collision>
      <origin xyz="4.49945e-74 -3.06162e-18 -0.11" rpy="-1.5708 3.19605e-84 -7.81881e-72"/>
      <geometry>
        <mesh filename="package://assets/link1.stl"/>
      </geometry>
    </collision>
  </link>
  <!-- Link link2 -->
  <link name="link2">
    <inertial>
      <origin xyz="3.82554e-20 -0.417115 -0.025" rpy="0 0 0"/>
      <mass value="24.9644"/>
      <inertia ixx="1.82621" ixy="-1.83512e-93" ixz="-5.91621e-116" iyy="0.0877481" iyz="2.77743e-209" izz="1.90356"/>
    </inertial>
    <!-- Part link2 -->
    <visual>
      <origin xyz="0 1.2 -0.17" rpy="-1.5708 1.58621e-116 -9.58807e-94"/>
      <geometry>
        <mesh filename="package://assets/link2.stl"/>
      </geometry>
      <material name="link2_material">
        <color rgba="0.231373 0.380392 0.705882 1.0"/>
      </material>
    </visual>
    <collision>
      <origin xyz="0 1.2 -0.17" rpy="-1.5708 1.58621e-116 -9.58807e-94"/>
      <geometry>
        <mesh filename="package://assets/link2.stl"/>
      </geometry>
    </collision>
  </link>
  <!-- Joint from link1 to link2 -->
  <joint name="joint2" type="revolute">
    <origin xyz="-1.25577e-33 -1.2 0.06" rpy="-2.17473e-28 2.02733e-28 2.93926e-56"/>
    <parent link="link1"/>
    <child link="link2"/>
    <axis xyz="0 0 1"/>
    <limit effort="1000" velocity="600" lower="-62.8319" upper="62.8319"/>
    <joint_properties friction="0.5"/>
  </joint>
  <!-- Joint from base to link1 -->
  <joint name="joint1" type="revolute">
    <origin xyz="2.23006e-29 -0.11 3.06162e-18" rpy="1.5708 -1.46963e-56 -2.02733e-28"/>
    <parent link="base"/>
    <child link="link1"/>
    <axis xyz="0 0 1"/>
    <limit effort="1000" velocity="600" lower="-62.8319" upper="62.8319"/>
    <joint_properties friction="0.5"/>
  </joint>
</robot>
