<?xml version="1.0" ?>
<!-- Generated using onshape-to-robot -->
<!-- Onshape https://cad.onshape.com/documents/3ebbb10823be46a55188b1ff/w/2488f47398571f659f3fde55/e/50a5d975662b86366b46b910 -->
<robot name="doublePendulem">
  <!-- Link base -->
  <link name="base">
    <inertial>
      <origin xyz="0 0 0" rpy="0 0 0"/>
      <mass value="0"/>
      <inertia ixx="0" ixy="0" ixz="0" iyy="0" iyz="0" izz="0"/>
    </inertial>
    <!-- Part base -->
    <visual>
      <origin xyz="0 0 0" rpy="0 -0 0"/>
      <geometry>
        <mesh filename="package://assets/base.stl"/>
      </geometry>
      <material name="base_material">
        <color rgba="0.615686 0.811765 0.929412 1.0"/>
      </material>
    </visual>
    <collision>
      <origin xyz="0 0 0" rpy="0 -0 0"/>
      <geometry>
        <mesh filename="package://assets/base.stl"/>
      </geometry>
    </collision>
  </link>
  <!-- Link link1 -->
  <link name="link1">
    <inertial>
      <origin xyz="-3.2373e-18 -0.0537081 -0.00455503" rpy="0 0 0"/>
      <mass value="0.0633724"/>
      <inertia ixx="7.1571e-05" ixy="0" ixz="0" iyy="2.86478e-06" iyz="1.30538e-06" izz="7.27655e-05"/>
    </inertial>
    <!-- Part link1 -->
    <visual>
      <origin xyz="0 -3.06162e-19 -0.022" rpy="-1.5708 -0 0"/>
      <geometry>
        <mesh filename="package://assets/link1.stl"/>
      </geometry>
      <material name="link1_material">
        <color rgba="0.647059 0.647059 0.647059 1.0"/>
      </material>
    </visual>
    <collision>
      <origin xyz="0 -3.06162e-19 -0.022" rpy="-1.5708 -0 0"/>
      <geometry>
        <mesh filename="package://assets/link1.stl"/>
      </geometry>
    </collision>
  </link>
  <!-- Link link2 -->
  <link name="link2">
    <inertial>
      <origin xyz="-7.41738e-19 -0.0517566 -0.005" rpy="0 0 0"/>
      <mass value="0.0608088"/>
      <inertia ixx="6.55015e-05" ixy="0" ixz="0" iyy="2.52035e-06" iyz="0" izz="6.70084e-05"/>
    </inertial>
    <!-- Part link2 -->
    <visual>
      <origin xyz="0 0.1 -0.034" rpy="-1.5708 -0 0"/>
      <geometry>
        <mesh filename="package://assets/link2.stl"/>
      </geometry>
      <material name="link2_material">
        <color rgba="0.231373 0.380392 0.705882 1.0"/>
      </material>
    </visual>
    <collision>
      <origin xyz="0 0.1 -0.034" rpy="-1.5708 -0 0"/>
      <geometry>
        <mesh filename="package://assets/link2.stl"/>
      </geometry>
    </collision>
  </link>
  <!-- Joint from link1 to link2 -->
  <joint name="joint2" type="continuous">
    <origin xyz="0 -0.1 0.012" rpy="0 -0 0"/>
    <parent link="link1"/>
    <child link="link2"/>
    <axis xyz="0 0 1"/>
    <limit effort="1000" velocity="600"/>
    <joint_properties friction="0.5"/>
  </joint>
  <!-- Joint from base to link1 -->
  <joint name="joint1" type="continuous">
    <origin xyz="0 -0.022 3.06162e-19" rpy="1.5708 -0 0"/>
    <parent link="base"/>
    <child link="link1"/>
    <axis xyz="0 0 1"/>
    <limit effort="1000" velocity="600"/>
    <joint_properties friction="0.5"/>
  </joint>
</robot>
