<?xml version="1.0" ?>
<!-- Generated using onshape-to-robot -->
<!-- Onshape https://cad.onshape.com/documents/15c938082851fbd4bacdce98/w/82abc59e7a8e49fa89bdf240/e/f0d3a1583e488bd8108149ec -->
<robot name="quadrupedCollision">
  <!-- Link bodysectioncola -->
  <link name="bodysectioncola">
    <inertial>
      <origin xyz="0 0 0" rpy="0 0 0"/>
      <mass value="1e-09"/>
      <inertia ixx="1e-09" ixy="0" ixz="0" iyy="1e-09" iyz="0" izz="1e-09"/>
    </inertial>
    <!-- Part bodysectioncola -->
    <visual>
      <origin xyz="0.0450888 -0.0589371 -0.0201511" rpy="9.0422e-60 8.81947e-28 1.2326e-32"/>
      <geometry>
        <mesh filename="package://assets/bodysectioncola.stl"/>
      </geometry>
      <material name="bodysectioncola_material">
        <color rgba="0.498039 0.498039 0.498039 1.0"/>
      </material>
    </visual>
    <collision>
      <origin xyz="0.0450888 -0.0589371 -0.0201511" rpy="9.0422e-60 8.81947e-28 1.2326e-32"/>
      <geometry>
        <mesh filename="package://assets/bodysectioncola.stl"/>
      </geometry>
    </collision>
  </link>
  <!-- Link coxamergecolr -->
  <link name="coxamergecolr">
    <inertial>
      <origin xyz="0 0 0" rpy="0 0 0"/>
      <mass value="1e-09"/>
      <inertia ixx="1e-09" ixy="0" ixz="0" iyy="1e-09" iyz="0" izz="1e-09"/>
    </inertial>
    <!-- Part coxamergecolr -->
    <visual>
      <origin xyz="-0.05 -5.75928e-16 -0.0635" rpy="1.5708 1.5708 0"/>
      <geometry>
        <mesh filename="package://assets/coxamergecolr.stl"/>
      </geometry>
      <material name="coxamergecolr_material">
        <color rgba="0.972549 0.529412 0.00392157 1.0"/>
      </material>
    </visual>
    <collision>
      <origin xyz="-0.05 -5.75928e-16 -0.0635" rpy="1.5708 1.5708 0"/>
      <geometry>
        <mesh filename="package://assets/coxamergecolr.stl"/>
      </geometry>
    </collision>
  </link>
  <!-- Link femurmergecolr -->
  <link name="femurmergecolr">
    <inertial>
      <origin xyz="0 0 0" rpy="0 0 0"/>
      <mass value="1e-09"/>
      <inertia ixx="1e-09" ixy="0" ixz="0" iyy="1e-09" iyz="0" izz="1e-09"/>
    </inertial>
    <!-- Part femurmergecolr -->
    <visual>
      <origin xyz="2.84495e-16 -2.498e-16 0.005" rpy="1.5708 -1.80753e-16 0.836756"/>
      <geometry>
        <mesh filename="package://assets/femurmergecolr.stl"/>
      </geometry>
      <material name="femurmergecolr_material">
        <color rgba="0.768627 0.886275 0.952941 1.0"/>
      </material>
    </visual>
    <collision>
      <origin xyz="2.84495e-16 -2.498e-16 0.005" rpy="1.5708 -1.80753e-16 0.836756"/>
      <geometry>
        <mesh filename="package://assets/femurmergecolr.stl"/>
      </geometry>
    </collision>
  </link>
  <!-- Link tibiamergecolr -->
  <link name="tibiamergecolr">
    <inertial>
      <origin xyz="0 0 0" rpy="0 0 0"/>
      <mass value="1e-09"/>
      <inertia ixx="1e-09" ixy="0" ixz="0" iyy="1e-09" iyz="0" izz="1e-09"/>
    </inertial>
    <!-- Part tibiamergecolr -->
    <visual>
      <origin xyz="0.0587099 0.365914 0.053" rpy="1.5708 4.16327e-14 2.24846"/>
      <geometry>
        <mesh filename="package://assets/tibiamergecolr.stl"/>
      </geometry>
      <material name="tibiamergecolr_material">
        <color rgba="0.917647 0.917647 0.917647 1.0"/>
      </material>
    </visual>
    <collision>
      <origin xyz="0.0587099 0.365914 0.053" rpy="1.5708 4.16327e-14 2.24846"/>
      <geometry>
        <mesh filename="package://assets/tibiamergecolr.stl"/>
      </geometry>
    </collision>
  </link>
  <!-- Joint from femurmergecolr to tibiamergecolr -->
  <joint name="kneeFE2" type="revolute">
    <origin xyz="-0.370594 1.67723e-11 -0.048" rpy="1.05471e-18 3.18941e-16 0.0675105"/>
    <parent link="femurmergecolr"/>
    <child link="tibiamergecolr"/>
    <axis xyz="0 0 1"/>
    <limit effort="10" velocity="10" lower="-2.72142" upper="0.450392"/>
  </joint>
  <!-- Joint from coxamergecolr to femurmergecolr -->
  <joint name="hipFE2" type="revolute">
    <origin xyz="-0.055 -6.53297e-15 -0.0635" rpy="-1.14895e-13 1.5708 0"/>
    <parent link="coxamergecolr"/>
    <child link="femurmergecolr"/>
    <axis xyz="0 0 1"/>
    <limit effort="10" velocity="10" lower="-3.7327" upper="0.456088"/>
  </joint>
  <!-- Joint from bodysectioncola to coxamergecolr -->
  <joint name="hipAA2" type="revolute">
    <origin xyz="-0.0184112 -0.00893707 -0.0201511" rpy="-1.5708 -5.55112e-17 1.5708"/>
    <parent link="bodysectioncola"/>
    <child link="coxamergecolr"/>
    <axis xyz="0 0 1"/>
    <limit effort="10" velocity="10" lower="-1.0472" upper="1.0472"/>
  </joint>
</robot>
