<robot name="single_pendulum">
    <!-- Connection to world frame -->
    <link name="world"/>
    <joint name="world_to_base" type="fixed">
        <parent link="world"/>
        <child link="base_link"/>
        <origin xyz="0 0 0" rpy="0 0 0"/>
    </joint>

    <link name="base_link">
        <inertial>
            <mass value="1.0" />
            <origin xyz="0 0 0" />
            <inertia ixx="0.01" iyy="0.01" izz="0.01" ixy="0.0" ixz="0.0" iyz="0.0" />
        </inertial>
        <visual>
            <geometry>
                <box size="0.1 0.1 0.1" />
            </geometry>
        </visual>
    </link>

    <link name="pendulum_link">
        <inertial>
            <mass value="0.5" />
            <origin xyz="0 0 -0.25" />
            <inertia ixx="0.001" iyy="0.001" izz="0.001" ixy="0.0" ixz="0.0" iyz="0.0" />
        </inertial>
        <visual>
            <geometry>
                <cylinder length="0.5" radius="0.05" />
            </geometry>
        </visual>
    </link>

    <joint name="hinge" type="revolute">
        <parent link="base_link" />
        <child link="pendulum_link" />
        <origin xyz="0 0 0.25" rpy="0 0 0" />
        <axis xyz="0 1 0" />
        <limit effort="10" velocity="5" lower="-3.14" upper="3.14" />
    </joint>
</robot>
